<?xml version="1.0" ?>
<!-- =================================================================================== -->
<!-- |    This document was autogenerated by xacro from vp6242.xacro                   | -->
<!-- |    EDITING THIS FILE BY HAND IS NOT RECOMMENDED                                 | -->
<!-- =================================================================================== -->
<robot name="vp6242" xmlns:xacro="http://www.ros.org/wiki/xacro">
  <link name="world"/>
  <link name="base_link">
    <inertial>
      <mass value="10"/>
      <inertia ixx="1.0" ixy="0.0" ixz="0.0" iyy="1.0" iyz="0.0" izz="1.0"/>
    </inertial>
    <visual>
      <geometry>
        <mesh filename="package://vp6242_description/meshes/visual/base.dae" scale="0.001 0.001 0.001"/>
      </geometry>
      <origin rpy="-1.570796 3.141592 0" xyz="0 0 0"/>
      <material name="blue">
        <color rgba="0 0 1 1"/>
      </material>
    </visual>
    <collision>
      <geometry>
        <mesh filename="package://vp6242_description/meshes/collision/base.dae" scale="0.001 0.001 0.001"/>
      </geometry>
      <origin rpy="-1.570796 3.141592 0" xyz="0 0 0"/>
      <material name="yellow">
        <color rgba="0 1 1 1"/>
      </material>
    </collision>
    <inertial>
      <origin rpy="0 0 0" xyz="0 0 0"/>
      <mass value="1"/>
      <inertia ixx="1.0" ixy="0.0" ixz="0.0" iyy="1.0" iyz="0.0" izz="1.0"/>
    </inertial>
  </link>
  <link name="link1">
    <inertial>
      <mass value="1"/>
      <inertia ixx="1.0" ixy="0.0" ixz="0.0" iyy="1.0" iyz="0.0" izz="1.0"/>
    </inertial>
    <visual>
      <geometry>
        <mesh filename="package://vp6242_description/meshes/visual/link1.dae" scale="0.001 0.001 0.001"/>
      </geometry>
      <origin rpy="-1.570796 3.141592 0" xyz="0 0 0"/>
    </visual>
    <collision>
      <geometry>
        <mesh filename="package://vp6242_description/meshes/collision/link1.dae" scale="0.001 0.001 0.001"/>
      </geometry>
      <origin rpy="-1.570796 3.141592 0" xyz="0 0 0"/>
    </collision>
  </link>
  <link name="link2">
    <inertial>
      <mass value="1"/>
      <inertia ixx="1.0" ixy="0.0" ixz="0.0" iyy="1.0" iyz="0.0" izz="1.0"/>
    </inertial>
    <visual>
      <geometry>
        <mesh filename="package://vp6242_description/meshes/visual/link2.dae" scale="0.001 0.001 0.001"/>
      </geometry>
      <origin rpy="-1.570796 3.141592 0" xyz="0 0 0"/>
    </visual>
    <collision>
      <geometry>
        <mesh filename="package://vp6242_description/meshes/collision/link2.dae" scale="0.001 0.001 0.001"/>
      </geometry>
      <origin rpy="-1.570796 3.141592 0" xyz="0 0 0"/>
    </collision>
    <inertial>
      <origin rpy="0 0 0" xyz="0 0 0"/>
      <mass value="1"/>
      <inertia ixx="1.0" ixy="0.0" ixz="0.0" iyy="1.0" iyz="0.0" izz="1.0"/>
    </inertial>
  </link>
  <link name="link3">
    <inertial>
      <mass value="1"/>
      <inertia ixx="1.0" ixy="0.0" ixz="0.0" iyy="1.0" iyz="0.0" izz="1.0"/>
    </inertial>
    <visual>
      <geometry>
        <mesh filename="package://vp6242_description/meshes/visual/link3.dae" scale="0.001 0.001 0.001"/>
      </geometry>
      <origin rpy="-1.570796 1.570796 0" xyz="0 0 0"/>
    </visual>
    <collision>
      <geometry>
        <mesh filename="package://vp6242_description/meshes/collision/link3.dae" scale="0.001 0.001 0.001"/>
      </geometry>
      <origin rpy="-1.570796 1.570796 0" xyz="0 0 0"/>
    </collision>
    <inertial>
      <origin rpy="0 0 0" xyz="0 0 0"/>
      <mass value="1"/>
      <inertia ixx="1.0" ixy="0.0" ixz="0.0" iyy="1.0" iyz="0.0" izz="1.0"/>
    </inertial>
  </link>
  <link name="link4">
    <inertial>
      <mass value="1"/>
      <inertia ixx="1.0" ixy="0.0" ixz="0.0" iyy="1.0" iyz="0.0" izz="1.0"/>
    </inertial>
    <visual>
      <geometry>
        <mesh filename="package://vp6242_description/meshes/visual/link4.dae" scale="0.001 0.001 0.001"/>
      </geometry>
      <origin rpy="0 1.570796 1.570796" xyz="0 0 0.085"/>
    </visual>
    <collision>
      <geometry>
        <mesh filename="package://vp6242_description/meshes/collision/link4.dae" scale="0.001 0.001 0.001"/>
      </geometry>
      <origin rpy="0 1.570796 1.570796" xyz="0 0 0.085"/>
    </collision>
    <inertial>
      <origin rpy="0 0 0" xyz="0 0 0"/>
      <mass value="1"/>
      <inertia ixx="1.0" ixy="0.0" ixz="0.0" iyy="1.0" iyz="0.0" izz="1.0"/>
    </inertial>
  </link>
  <link name="link5">
    <inertial>
      <mass value="1"/>
      <inertia ixx="1.0" ixy="0.0" ixz="0.0" iyy="1.0" iyz="0.0" izz="1.0"/>
    </inertial>
    <visual>
      <geometry>
        <mesh filename="package://vp6242_description/meshes/visual/link5.dae" scale="0.001 0.001 0.001"/>
      </geometry>
      <origin rpy="0 1.570796 1.570796" xyz="0 0 0.0"/>
    </visual>
    <collision>
      <geometry>
        <mesh filename="package://vp6242_description/meshes/collision/link5.dae" scale="0.001 0.001 0.001"/>
      </geometry>
      <origin rpy="0 1.570796 1.570796" xyz="0 0 0.0"/>
    </collision>
    <inertial>
      <origin rpy="0 0 0" xyz="0 0 0"/>
      <mass value="1"/>
      <inertia ixx="1.0" ixy="0.0" ixz="0.0" iyy="1.0" iyz="0.0" izz="1.0"/>
    </inertial>
  </link>
  <link name="link6">
    <visual>
      <geometry>
        <cylinder length="0.01" radius="0.0205"/>
      </geometry>
      <origin rpy="0 0 0" xyz="0.0 0.0 -0.005"/>
      <material name="plate">
        <color rgba="0.1 0.1 0.1 0.8"/>
      </material>
    </visual>
  </link>
  <link name="tool0"/>
  <joint name="world-base" type="fixed">
    <parent link="world"/>
    <child link="base_link"/>
  </joint>
  <joint name="joint1" type="revolute">
    <origin rpy="0 0 0" xyz="0.0 0.0 0.155"/>
    <parent link="base_link"/>
    <child link="link1"/>
    <axis xyz="0 0 1"/>
    <limit effort="0" lower="-2.792526803" upper="2.792526803" velocity="1.0"/>
    <dynamics damping="0.7"/>
  </joint>
  <joint name="joint2" type="revolute">
    <origin rpy="0 0 0" xyz="0.0 0.0 0.125"/>
    <parent link="link1"/>
    <child link="link2"/>
    <axis xyz="0 1 0"/>
    <limit effort="0" lower="-2.094395102" upper="2.094395102" velocity="1.0"/>
    <dynamics damping="0.7"/>
  </joint>
  <joint name="joint3" type="revolute">
    <origin rpy="0 0 0" xyz="0.0 0.0 0.210"/>
    <parent link="link2"/>
    <child link="link3"/>
    <axis xyz="0 1 0"/>
    <limit effort="0" lower="0.331612558" upper="2.792526803" velocity="1.0"/>
    <dynamics damping="0.7"/>
  </joint>
  <joint name="joint4" type="revolute">
    <origin rpy="0 0 0" xyz="-0.075 0.0 0.0"/>
    <parent link="link3"/>
    <child link="link4"/>
    <axis xyz="0 0 1"/>
    <limit effort="0" lower="-2.792526803" upper="2.792526803" velocity="1.0"/>
    <dynamics damping="0.7"/>
  </joint>
  <joint name="joint5" type="revolute">
    <origin rpy="0 0 0" xyz="0.0 0.0 0.210"/>
    <parent link="link4"/>
    <child link="link5"/>
    <axis xyz="0 1 0"/>
    <limit effort="0" lower="-2.094395102" upper="2.094395102" velocity="1.0"/>
    <dynamics damping="0.7"/>
  </joint>
  <joint name="joint6" type="revolute">
    <origin rpy="0 0 0" xyz="0.0 0.0 0.07"/>
    <parent link="link5"/>
    <child link="link6"/>
    <axis xyz="0 0 1"/>
    <limit effort="0" lower="-6.283185307" upper="6.283185307" velocity="1.0"/>
    <dynamics damping="0.7"/>
  </joint>
  <joint name="joint6-tool0" type="fixed">
    <parent link="link6"/>
    <child link="tool0"/>
    <origin rpy="0 0 0" xyz="0 0 0"/>
  </joint>
</robot>

